Workbook

Sheet Cover_Page
G4: Business Valuation (Individual Project)
I5: Shrishti Raizada
I6: MBA24253
I7: Sec B
I8: Bajaj Auto Limited

Sheet DCF
A1: Unlevered Free Cash Flow (Cr) | G1: Projections
A2: Projection Year | G2: 1 | H2: 2 | I2: 3 | J2: 4 | K2: 5 | L2: 6 | M2: 7
A3: Fiscal Year | B3: Mar-2021 | C3: Mar-2022 | D3: Mar-2023 | E3: 45352 | F3: Mar-2025 | G3: 46082 | H3: 46447 | I3: 46813 | J3: 47178 | K3: 47543 | L3: 47908 | M3: 48274
A5: Unlevered Free Cash Flow | B5: =FCFF_Projections!B21 -> 5398.4 | C5: =FCFF_Projections!C21 -> 6198.43 | D5: =FCFF_Projections!D21 -> 9122.8 | E5: =FCFF_Projections!E21 -> 7984.07 | F5: =FCFF_Projections!F21 -> 9981.9897 | G5: =FCFF_Projections!G21 -> 11350.809 | H5: =FCFF_Projections!H21 -> 13514.116 | I5: =FCFF_Projections!I21 -> 15637.641 | ... M5: =FCFF_Projections!M21 -> 18806.656
A8: Present Value of Free Cash Flow | G8: =G5/(1+$B$13)^G2 -> 9737.4829 | H8: =H5/(1+$B$13)^H2 -> 9945.5184 | I8: =I5/(1+$B$13)^I2 -> 9872.5858 | J8: =J5/(1+$B$13)^J2 -> 9221.8274 | K8: =K5/(1+$B$13)^K2 -> 9312.7963 | L8: =L5/(1+$B$13)^L2 -> 9205.9458 | M8: =M5/(1+$B$13)^M2 -> 6430.59
A11: Sum of PV of FCF | B11: =SUM(G8:M8) -> 63726.747 | G11: Sensitivity Table
A12: Growth Rate | B12: 0.05
A13: WACC | B13: =WACC!B17 -> 0.16568205 | I13: Growth Rate
A14: Terminal Value | B14: =(M8*(1+B12))/(B13-B12) -> 58367.91 | H14: =B22 -> 1150.9825 | I14: 0.04 | J14: =K14-0.5% -> 0.045 | K14: =B12 -> 0.05 | L14: =K14+0.5% -> 0.055 | M14: =L14+0.5% -> 0.06
A15: PV of Terminal Value | B15: =B14/(1+B13)^7 -> 19957.833 | G15: WACC | H15: =H16-0.5% -> 0.15568205 | I15: 1150.9825 | J15: 1150.9825 | K15: 1150.9825 | L15: 1150.9825 | M15: 1150.9825
A16: Enterprise Value | B16: =B11+B14 -> 122094.66 | H16: =H17-0.5% -> 0.16068205 | I16: 1150.9825 | J16: 1150.9825 | K16: 1150.9825 | L16: 1150.9825 | M16: 1150.9825
A17: (+) Cash | B17: ='Balance_Sheet (5 years)'!F43 -> 1328.55 | H17: =B13 -> 0.16568205 | I17: 1150.9825 | J17: 1150.9825 | K17: 1150.9825 | L17: 1150.9825 | M17: 1150.9825
A18: (-) Debt | B18: ='Balance_Sheet (5 years)'!F53 -> 927.64 | H18: =H17+0.5% -> 0.17068205 | I18: 1150.9825 | J18: 1150.9825 | K18: 1150.9825 | L18: 1150.9825 | M18: 1150.9825
A19: (-) Minority Interest | B19: 0 | H19: =H18+0.5% -> 0.17568205 | I19: 1150.9825 | J19: 1150.9825 | K19: 1150.9825 | L19: 1150.9825 | M19: 1150.9825
A20: Equity Value | B20: ='Balance_Sheet (5 years)'!F7 -> 32146.94
A21: Diluted Shares Outstanding (mm) | B21: 27.93
A22: Implied Share Price | B22: =B20/B21 -> 1150.9825

Sheet FCFF_Projections
G1: Projections
A2: Particulars | B2: Mar-2021 | C2: Mar-2022 | D2: Mar-2023 | E2: 45352 | F2: Mar-2025 | G2: 46082 | H2: 46447 | I2: 46813 | J2: 47178 | K2: 47543 | L2: 47908 | M2: 48274
A3: Revenue | B3: ='Income_Statement (5 years)'!B9 -> 27741.08 | C3: ='Income_Statement (5 years)'!C9 -> 33144.71 | D3: ='Income_Statement (5 years)'!D9 -> 36427.6 | E3: ='Income_Statement (5 years)'!E9 -> 44685.23 | F3: ='Income_Statement (5 years)'!F9 -> 50010.31 | G3: =F3*(1+G25) -> 58008.083 | H3: =G3*(1+H25) -> 66779.26 | I3: =H3*(1+I25) -> 77747.476 | J3: =I3*(1+J25) -> 89303.532 | K3: =J3*(1+K25) -> 103235.11 | L3: =K3*(1+L25) -> 119238.88 | M3: =L3*(1+M25) -> 137837.37
A4: COGS | B4: ='Income_Statement (5 years)'!B12 -> 19829.13 | C4: ='Income_Statement (5 years)'!C12 -> 24141.86 | D4: ='Income_Statement (5 years)'!D12 -> 26152.86 | E4: ='Income_Statement (5 years)'!E12 -> 31813.89 | F4: ='Income_Statement (5 years)'!F12 -> 35302.26 | G4: =G27*G3 -> 41521.795 | H4: =H27*H3 -> 47813.503 | I4: =I27*I3 -> 55474.105 | J4: =J27*J3 -> 63640.52 | K4: =K27*K3 -> 73582.567 | L4: =L27*L3 -> 85153.293 | M4: =M27*M3 -> 98389.654
A5: Gross Profit | B5: =B3-B4 -> 7911.95 | C5: =C3-C4 -> 9002.85 | D5: =D3-D4 -> 10274.74 | E5: =E3-E4 -> 12871.34 | F5: =F3-F4 -> 14708.05 | G5: =G3-G4 -> 16486.288 | H5: =H3-H4 -> 18965.757 | I5: =I3-I4 -> 22273.371 | ... M5: =M3-M4 -> 39447.717
A6: Operating Expenses
A7: Selling, General, Administrative | B7: =SUM('Income_Statement (5 years)'!B16,'Income_Statement (5 years)'!B17) -> 557.68 | C7: =SUM('Income_Statement (5 years)'!C16,'Income_Statement (5 years)'!C17) -> 542.48 | D7: =SUM('Income_Statement (5 years)'!D16,'Income_Statement (5 years)'!D17) -> 674.3 | E7: =SUM('Income_Statement (5 years)'!E16,'Income_Statement (5 years)'!E17) -> 761.73 | F7: =SUM('Income_Statement (5 years)'!F16,'Income_Statement (5 years)'!F17) -> 857.24 | G7: =G28*G3 -> 1034.4997 | H7: =H28*H3 -> 1160.6137 | I7: =I28*I3 -> 1366.9887 | J7: =J28*J3 -> 1553.5926 | K7: =K28*K3 -> 1803.1874 | L7: =L28*L3 -> 2090.4855 | M7: =M28*M3 -> 2408.2325
A8: Total Operating Expenses | B8: =B7 -> 557.68 | C8: =C7 -> 542.48 | D8: =D7 -> 674.3 | E8: =E7 -> 761.73 | F8: =F7 -> 857.24 | G8: =G7 -> 1034.4997 | H8: =H7 -> 1160.6137 | I8: =I7 -> 1366.9887 | ... M8: =M7 -> 2408.2325
A9: EBITDA | B9: =B5-B8 -> 7354.27 | C9: =C5-C8 -> 8460.37 | D9: =D5-D8 -> 9600.44 | E9: =E5-E8 -> 12109.61 | F9: =F5-F8 -> 13850.81 | G9: =G5-G8 -> 15451.789 | H9: =H5-H8 -> 17805.143 | I9: =I5-I8 -> 20906.382 | ... M9: =M5-M8 -> 37039.484
A10: Depreciation & Amortization | B10: ='Income_Statement (5 years)'!B26 -> 259.28 | C10: ='Income_Statement (5 years)'!C26 -> 269.17 | D10: ='Income_Statement (5 years)'!D26 -> 282.44 | E10: ='Income_Statement (5 years)'!E26 -> 349.84 | F10: ='Income_Statement (5 years)'!F26 -> 400.09 | G10: =Fixed_Assets!G4 -> 559.30329 | H10: =Fixed_Assets!H4 -> 663.91289 | I10: =Fixed_Assets!I4 -> 752.14763 | J10: =Fixed_Assets!J4 -> 919.32148 | K10: =Fixed_Assets!K4 -> 1137.5453 | L10: =Fixed_Assets!L4 -> 1397.4192 | M10: =Fixed_Assets!M4 -> 1663.474
A11: Operating Profit (EBIT) | B11: =B9-B10 -> 7094.99 | C11: =C9-C10 -> 8191.2 | D11: =D9-D10 -> 9318 | E11: =E9-E10 -> 11759.77 | F11: =F9-F10 -> 13450.72 | G11: =G9-G10 -> 14892.485 | H11: =H9-H10 -> 17141.23 | I11: =I9-I10 -> 20154.234 | ... M11: =M9-M10 -> 35376.01
A12: Operating Taxes | B12: ='Income_Statement (5 years)'!B31 -> 1384.41 | C12: ='Income_Statement (5 years)'!C31 -> 1486.46 | D12: ='Income_Statement (5 years)'!D31 -> 1781.04 | E12: ='Income_Statement (5 years)'!E31 -> 2343.22 | F12: ='Income_Statement (5 years)'!F31 -> 2900.47 | G12: =G29*G11 -> 2926.7581 | H12: =H29*H11 -> 3373.4969 | I12: =I29*I11 -> 4028.2899 | J12: =J29*J11 -> 4675.5831 | K12: =K29*K11 -> 5398.252 | L12: =L29*L11 -> 6100.6713 | M12: =M29*M11 -> 7073.6078
A13: NOPAT (Net Operating Profit After Taxes) | B13: =B11-B12 -> 5710.58 | C13: =C11-C12 -> 6704.74 | D13: =D11-D12 -> 7536.96 | E13: =E11-E12 -> 9416.55 | F13: =F11-F12 -> 10550.25 | G13: =G11-G12 -> 11965.727 | H13: =H11-H12 -> 13767.733 | I13: =I11-I12 -> 16125.944 | ... M13: =M11-M12 -> 28302.402
A14: (+) Depreciation & Amortization | B14: =B10 -> 259.28 | C14: =C10 -> 269.17 | D14: =D10 -> 282.44 | E14: =E10 -> 349.84 | F14: =F10 -> 400.09 | G14: =G10 -> 559.30329 | H14: =H10 -> 663.91289 | I14: =I10 -> 752.14763 | ... M14: =M10 -> 1663.474
A15: (-) Capital Expenditures | B15: =Fixed_Assets!B5 -> 429.54 | C15: =Fixed_Assets!C5 -> 1152.27 | D15: =Fixed_Assets!D5 -> 766.21 | E15: =Fixed_Assets!E5 -> 703.06 | F15: =Fixed_Assets!F5 -> 1246.4178 | G15: =Fixed_Assets!G5 -> 1644.8235 | H15: =Fixed_Assets!H5 -> 1691.0593 | I15: =Fixed_Assets!I5 -> 2049.0273 | ... M15: =Fixed_Assets!M5 -> 4591.5476
A16: (-) Change in NWC | B16: =C17-B17 -> 141.92 | C16: =D17-C17 -> -376.79 | D16: =E17-D17 -> -2069.61 | E16: =F17-E17 -> 1079.26 | F16: =G17-F17 -> -278.06742 | G16: =H17-G17 -> -470.60202 | H16: =I17-H17 -> -773.52935 | I16: =J17-I17 -> -808.57639 | ... M16: =N17-M17 -> 6567.6724
A17: NWC | B17: =B18-B19 -> -1022.63 | C17: =C18-C19 -> -880.71 | D17: =D18-D19 -> -1257.5 | E17: =E18-E19 -> -3327.11 | F17: =F18-F19 -> -2247.85 | G17: =G18-G19 -> -2525.9174 | H17: =H18-H19 -> -2996.5194 | I17: =I18-I19 -> -3770.0488 | ... M17: =M18-M19 -> -6567.6724
A18: Current Assets | B18: =Net_Working_Capital!B6 -> 4444.06 | C18: =Net_Working_Capital!C6 -> 3630.83 | D18: =Net_Working_Capital!D6 -> 3750.85 | E18: =Net_Working_Capital!E6 -> 4349.9 | F18: =Net_Working_Capital!F6 -> 5475.24 | G18: =Net_Working_Capital!G6 -> 6724.4112 | H18: =Net_Working_Capital!H6 -> 7149.5591 | I18: =Net_Working_Capital!I6 -> 8284.5062 | ... M18: =Net_Working_Capital!M6 -> 14868.994
A19: Current Liabilitites | B19: =Net_Working_Capital!B10 -> 5466.69 | C19: =Net_Working_Capital!C10 -> 4511.54 | D19: =Net_Working_Capital!D10 -> 5008.35 | E19: =Net_Working_Capital!E10 -> 7677.01 | F19: =Net_Working_Capital!F10 -> 7723.09 | G19: =Net_Working_Capital!G10 -> 9250.3286 | H19: =Net_Working_Capital!H10 -> 10146.079 | I19: =Net_Working_Capital!I10 -> 12054.555 | ... M19: =Net_Working_Capital!M10 -> 21436.667
A21: Unlevered Free Cash Flow | B21: =B13+B14-B15-B16 -> 5398.4 | C21: =C13+C14-C15-C16 -> 6198.43 | D21: =D13+D14-D15-D16 -> 9122.8 | E21: =E13+E14-E15-E16 -> 7984.07 | F21: =F13+F14-F15-F16 -> 9981.9897 | G21: =G13+G14-G15-G16 -> 11350.809 | H21: =H13+H14-H15-H16 -> 13514.116 | I21: =I13+I14-I15-I16 -> 15637.641 | ... M21: =M13+M14-M15-M16 -> 18806.656
A23: Assumptions
A24: =A2 -> Particulars
A25: Revenue Growth | C25: =C3/B3-1 -> 0.19478802 | D25: =D3/C3-1 -> 0.099047178 | E25: =E3/D3-1 -> 0.22668608 | F25: =F3/E3-1 -> 0.11916868 | G25: =AVERAGE(C25:F25) -> 0.15992249 | H25: =AVERAGE(D25:G25) -> 0.15120611 | I25: =AVERAGE(E25:H25) -> 0.16424584 | J25: =AVERAGE(F25:I25) -> 0.14863578 | K25: =AVERAGE(G25:J25) -> 0.15600256 | L25: =AVERAGE(H25:K25) -> 0.15502257 | M25: =AVERAGE(I25:L25) -> 0.15597669
A27: COGS % of Revenue | B27: =B4/B3 -> 0.71479301 | C27: =C4/C3 -> 0.72837747 | D27: =D4/D3 -> 0.71794079 | E27: =E4/E3 -> 0.71195538 | F27: =F4/F3 -> 0.70589964 | G27: =AVERAGE(B27:F27) -> 0.71579326 | H27: =AVERAGE(C27:G27) -> 0.71599331 | I27: =AVERAGE(D27:H27) -> 0.71351648 | J27: =AVERAGE(E27:I27) -> 0.71263161 | K27: =AVERAGE(F27:J27) -> 0.71276686 | L27: =AVERAGE(G27:K27) -> 0.7141403 | M27: =AVERAGE(H27:L27) -> 0.71380971
A28: SG&A % of Revenue | B28: =B7/B3 -> 0.020103039 | C28: =C7/C3 -> 0.016367016 | D28: =D7/D3 -> 0.01851069 | E28: =E7/E3 -> 0.017046572 | F28: =F7/F3 -> 0.017141265 | G28: =AVERAGE(B28:F28) -> 0.017833716 | H28: =AVERAGE(C28:G28) -> 0.017379852 | I28: =AVERAGE(D28:H28) -> 0.017582419 | J28: =AVERAGE(E28:I28) -> 0.017396765 | K28: =AVERAGE(F28:J28) -> 0.017466804 | L28: =AVERAGE(G28:K28) -> 0.017531911 | M28: =AVERAGE(H28:L28) -> 0.01747155
A29: Tax % of EBIT | B29: =B12/B11 -> 0.19512501 | C29: =C12/C11 -> 0.18147036 | D29: =D12/D11 -> 0.19113973 | E29: =E12/E11 -> 0.1992573 | F29: =F12/F11 -> 0.21563678 | G29: =AVERAGE(B29:F29) -> 0.19652584 | H29: =AVERAGE(C29:G29) -> 0.196806 | I29: =AVERAGE(D29:H29) -> 0.19987313 | J29: =AVERAGE(E29:I29) -> 0.20161981 | K29: =AVERAGE(F29:J29) -> 0.20209231 | L29: =AVERAGE(G29:K29) -> 0.19938342 | M29: =AVERAGE(H29:L29) -> 0.19995493

Sheet WACC
A1: Weighted Average Cost of Capital (WACC)
A2: Equity (mm) | B2: ='Balance_Sheet (5 years)'!F7 -> 32146.94
A3: Debt (mm) | B3: ='Balance_Sheet (5 years)'!F53 -> 927.64
A5: Cost of Debt | B5: ='Income_Statement (5 years)'!F24/WACC!B3 -> 0.073002458
A6: Tax Rate | B6: 0.3
A7: D/(D+E) | B7: =B3/(B3+B2) -> 0.028046917
A8: After Tax Cost of Debt | B8: =B5*(1-B6) -> 0.05110172
A10: Risk Free Rate (10-Yr Treasury Yield) | B10: ='Risk-free_rate'!L8 -> 0.0697
A11: Expected Market Return | B11: =Beta_Calculation!I7 -> 0.19864599
A12: Market Risk Premium | B12: =B11-B10 -> 0.12894599
A13: Levered Beta | B13: =Beta_Calculation!H3 -> 0.77
A14: E/(D+E) | B14: =B2/(B2+B3) -> 0.97195308
A15: Cost of Equity | B15: =B10+B13*(B12) -> 0.16898841
A17: WACC | B17: =(B7*B8)+(B15*B14) -> 0.16568205

Sheet Net_Working_Capital
A1: Net Working Capital | G1: Projections
A2: Fiscal Year | B2: Mar-2021 | C2: Mar-2022 | D2: Mar-2023 | E2: 45352 | F2: Mar-2025 | G2: 46082 | H2: 46447 | I2: 46813 | J2: 47178 | K2: 47543 | L2: 47908 | M2: 48274
A3: Accounts Receivables | B3: ='Balance_Sheet (5 years)'!B42 -> 2716.85 | C3: ='Balance_Sheet (5 years)'!C42 -> 1516.38 | D3: ='Balance_Sheet (5 years)'!D42 -> 1776.12 | E3: ='Balance_Sheet (5 years)'!E42 -> 2122.4 | F3: ='Balance_Sheet (5 years)'!F42 -> 2282.64 | G3: =G17*G14/365 -> 3313.2346 | H3: =H17*H14/365 -> 3269.0406 | I3: =I17*I14/365 -> 3855.7665 | J3: =J17*J14/365 -> 4443.8016 | K3: =K17*K14/365 -> 5183.7902 | L3: =L17*L14/365 -> 6096.3803 | M3: =M17*M14/365 -> 6882.163
A4: Merchandise Inventory | B4: ='Balance_Sheet (5 years)'!B41 -> 1493.89 | C4: ='Balance_Sheet (5 years)'!C41 -> 1230.51 | D4: ='Balance_Sheet (5 years)'!D41 -> 1397.9 | E4: ='Balance_Sheet (5 years)'!E41 -> 1695.62 | F4: ='Balance_Sheet (5 years)'!F41 -> 1957.9 | G4: =G18*G15/365 -> 2395.9604 | H4: =H18*H15/365 -> 2590.3819 | I4: =I18*I15/365 -> 3040.9877 | J4: =J18*J15/365 -> 3506.055 | K4: =K18*K15/365 -> 4080.171 | L4: =L18*L15/365 -> 4721.5867 | M4: =M18*M15/365 -> 5411.132
A5: Other Current Assets | B5: ='Balance_Sheet (5 years)'!B44 -> 233.32 | C5: ='Balance_Sheet (5 years)'!C44 -> 883.94 | D5: ='Balance_Sheet (5 years)'!D44 -> 576.83 | E5: ='Balance_Sheet (5 years)'!E44 -> 531.88 | F5: ='Balance_Sheet (5 years)'!F44 -> 1234.7 | G5: =G21*G14 -> 1015.2162 | H5: =H21*H14 -> 1290.1365 | I5: =I21*I14 -> 1387.752 | J5: =J21*J14 -> 1630.0022 | K5: =K21*K14 -> 2015.3864 | L5: =L21*L14 -> 2204.6045 | M5: =M21*M14 -> 2575.6994
A6: Current Assets | B6: =SUM(B3:B5) -> 4444.06 | C6: =SUM(C3:C5) -> 3630.83 | D6: =SUM(D3:D5) -> 3750.85 | E6: =SUM(E3:E5) -> 4349.9 | F6: =SUM(F3:F5) -> 5475.24 | G6: =SUM(G3:G5) -> 6724.4112 | H6: =SUM(H3:H5) -> 7149.5591 | I6: =SUM(I3:I5) -> 8284.5062 | ... M6: =SUM(M3:M5) -> 14868.994
A8: Accounts Payable | B8: ='Balance_Sheet (5 years)'!B17 -> 4573.81 | C8: ='Balance_Sheet (5 years)'!C17 -> 3633.18 | D8: ='Balance_Sheet (5 years)'!D17 -> 4073.88 | E8: ='Balance_Sheet (5 years)'!E17 -> 5593.61 | F8: ='Balance_Sheet (5 years)'!F17 -> 6267.63 | G8: =G19*G15/365 -> 7393.2941 | H8: =H19*H15/365 -> 8010.5574 | I8: =I19*I15/365 -> 9483.1025 | J8: =J19*J15/365 -> 11072.266 | K8: =K19*K15/365 -> 12774.897 | L8: =L19*L15/365 -> 14716.816 | M8: =M19*M15/365 -> 16901.49
A9: Other Current Liabilities | B9: ='Balance_Sheet (5 years)'!B18 -> 892.88 | C9: ='Balance_Sheet (5 years)'!C18 -> 878.36 | D9: ='Balance_Sheet (5 years)'!D18 -> 934.47 | E9: ='Balance_Sheet (5 years)'!E18 -> 2083.4 | F9: ='Balance_Sheet (5 years)'!F18 -> 1455.46 | G9: =G22*G14 -> 1857.0345 | H9: =H22*H14 -> 2135.5211 | I9: =I22*I14 -> 2571.4525 | J9: =J22*J14 -> 3086.2177 | K9: =K22*K14 -> 3318.5658 | L9: =L22*L14 -> 3905.5754 | M9: =M22*M14 -> 4535.1771
A10: Current Liabilities | B10: =SUM(B8:B9) -> 5466.69 | C10: =SUM(C8:C9) -> 4511.54 | D10: =SUM(D8:D9) -> 5008.35 | E10: =SUM(E8:E9) -> 7677.01 | F10: =SUM(F8:F9) -> 7723.09 | G10: =SUM(G8:G9) -> 9250.3286 | H10: =SUM(H8:H9) -> 10146.079 | I10: =SUM(I8:I9) -> 12054.555 | ... M10: =SUM(M8:M9) -> 21436.667
A12: Assumptions
A13: Fiscal Year | B13: Mar-2021 | C13: Mar-2022 | D13: Mar-2023 | E13: 45352 | F13: Mar-2025 | G13: 46082 | H13: 46447 | I13: 46813 | J13: 47178 | K13: 47543 | L13: 47908 | M13: 48274
A14: Revenue | B14: =FCFF_Projections!B3 -> 27741.08 | C14: =FCFF_Projections!C3 -> 33144.71 | D14: =FCFF_Projections!D3 -> 36427.6 | E14: =FCFF_Projections!E3 -> 44685.23 | F14: =FCFF_Projections!F3 -> 50010.31 | G14: =FCFF_Projections!G3 -> 58008.083 | H14: =FCFF_Projections!H3 -> 66779.26 | I14: =FCFF_Projections!I3 -> 77747.476 | ... M14: =FCFF_Projections!M3 -> 137837.37
A15: COGS | B15: =FCFF_Projections!B4 -> 19829.13 | C15: =FCFF_Projections!C4 -> 24141.86 | D15: =FCFF_Projections!D4 -> 26152.86 | E15: =FCFF_Projections!E4 -> 31813.89 | F15: =FCFF_Projections!F4 -> 35302.26 | G15: =FCFF_Projections!G4 -> 41521.795 | H15: =FCFF_Projections!H4 -> 47813.503 | I15: =FCFF_Projections!I4 -> 55474.105 | ... M15: =FCFF_Projections!M4 -> 98389.654
A17: Days Sales Outstanding (DSO) | B17: =(B3/B14)*365 -> 35.746635 | C17: =(C3/C14)*365 -> 16.698855 | D17: =(D3/D14)*365 -> 17.7965 | E17: =(E3/E14)*365 -> 17.336288 | F17: =(F3/F14)*365 -> 16.659837 | G17: =AVERAGE(B17:F17) -> 20.847623 | H17: =AVERAGE(C17:G17) -> 17.86782 | I17: =AVERAGE(D17:H17) -> 18.101614 | J17: =AVERAGE(E17:I17) -> 18.162636 | K17: =AVERAGE(F17:J17) -> 18.327906 | L17: =AVERAGE(G17:K17) -> 18.66152 | M17: =AVERAGE(H17:L17) -> 18.224299
A18: Days Inventory Outstanding (DIO) | B18: =B4/B15*365 -> 27.498425 | C18: =C4/C15*365 -> 18.604041 | D18: =D4/D15*365 -> 19.509664 | E18: =E4/E15*365 -> 19.453808 | F18: =F4/F15*365 -> 20.243279 | G18: =AVERAGE(B18:F18) -> 21.061843 | H18: =AVERAGE(C18:G18) -> 19.774527 | I18: =AVERAGE(D18:H18) -> 20.008624 | J18: =AVERAGE(E18:I18) -> 20.108416 | K18: =AVERAGE(F18:J18) -> 20.239338 | L18: =AVERAGE(G18:K18) -> 20.23855 | M18: =AVERAGE(H18:L18) -> 20.073891
A19: Days Payable Outstanding (DPO) | B19: =B8/B15*365 -> 84.191321 | C19: =C8/C15*365 -> 54.929931 | D19: =D8/D15*365 -> 56.856734 | E19: =E8/E15*365 -> 64.175354 | F19: =F8/F15*365 -> 64.80279 | G19: =AVERAGE(B19:F19) -> 64.991226 | H19: =AVERAGE(C19:G19) -> 61.151207 | I19: =AVERAGE(D19:H19) -> 62.395462 | J19: =AVERAGE(E19:I19) -> 63.503208 | K19: =AVERAGE(F19:J19) -> 63.368779 | L19: =AVERAGE(G19:K19) -> 63.081976 | M19: =AVERAGE(H19:L19) -> 62.700126
A21: Other Current Assets as a % of Revenue | B21: =B5/B14 -> 0.0084106315 | C21: =C5/C14 -> 0.026669113 | D21: =D5/D14 -> 0.015834971 | E21: =E5/E14 -> 0.011902814 | F21: =F5/F14 -> 0.024688909 | G21: =AVERAGE(B21:F21) -> 0.017501288 | H21: =AVERAGE(C21:G21) -> 0.019319419 | I21: =AVERAGE(D21:H21) -> 0.01784948 | J21: =AVERAGE(E21:I21) -> 0.018252382 | K21: =AVERAGE(F21:J21) -> 0.019522296 | L21: =AVERAGE(G21:K21) -> 0.018488973 | M21: =AVERAGE(H21:L21) -> 0.01868651
A22: Other Current Liabilities as a % of Revenue | B22: =B9/B14 -> 0.032186202 | C22: =C9/C14 -> 0.02650076 | D22: =D9/D14 -> 0.025652802 | E22: =E9/E14 -> 0.046623907 | F22: =F9/F14 -> 0.029103199 | G22: =AVERAGE(B22:F22) -> 0.032013374 | H22: =AVERAGE(C22:G22) -> 0.031978808 | I22: =AVERAGE(D22:H22) -> 0.033074418 | J22: =AVERAGE(E22:I22) -> 0.034558741 | K22: =AVERAGE(F22:J22) -> 0.032145708 | L22: =AVERAGE(G22:K22) -> 0.03275421 | M22: =AVERAGE(H22:L22) -> 0.032902377

Sheet Fixed_Assets
A1: Fixed Assets Schedule | G1: Projections
A2: Fiscal Year | B2: Mar-2021 | C2: Mar-2022 | D2: Mar-2023 | E2: 45352 | F2: Mar-2025 | G2: 46082 | H2: 46447 | I2: 46813 | J2: 47178 | K2: 47543 | L2: 47908 | M2: 48274
A3: Beginning PP&E | B3: ='Balance_Sheet (5 years)'!B29 -> 1612.63 | C3: ='Balance_Sheet (5 years)'!C29 -> 1782.89 | D3: ='Balance_Sheet (5 years)'!D29 -> 2665.99 | E3: ='Balance_Sheet (5 years)'!E29 -> 3149.76 | F3: ='Balance_Sheet (5 years)'!F29 -> 3502.98 | G3: =F3-F4+F5 -> 4349.3078 | H3: =G6 -> 5434.828 | I3: =H6 -> 6461.9744 | J3: =I6 -> 7758.8541 | K3: =J6 -> 9481.8865 | L3: =K6 -> 11537.325 | M3: =L6 -> 13905.539
A4: D&A | B4: ='Income_Statement (5 years)'!B26 -> 259.28 | C4: ='Income_Statement (5 years)'!C26 -> 269.17 | D4: ='Income_Statement (5 years)'!D26 -> 282.44 | E4: ='Income_Statement (5 years)'!E26 -> 349.84 | F4: ='Income_Statement (5 years)'!F26 -> 400.09 | G4: =G10*G3 -> 559.30329 | H4: =H10*H3 -> 663.91289 | I4: =I10*I3 -> 752.14763 | J4: =J10*J3 -> 919.32148 | K4: =K10*K3 -> 1137.5453 | L4: =L10*L3 -> 1397.4192 | M4: =M10*M3 -> 1663.474
A5: CapEx | B5: =B6-B3+B4 -> 429.54 | C5: =C6-C3+C4 -> 1152.27 | D5: =D6-D3+D4 -> 766.21 | E5: =E6-E3+E4 -> 703.06 | F5: =F11*F3 -> 1246.4178 | G5: =G11*G3 -> 1644.8235 | H5: =H11*H3 -> 1691.0593 | I5: =I11*I3 -> 2049.0273 | J5: =J11*J3 -> 2642.3539 | K5: =K11*K3 -> 3192.9841 | L5: =L11*L3 -> 3765.6323 | M5: =M11*M3 -> 4591.5476
A6: Ending PP&E | B6: ='Balance_Sheet (5 years)'!C29 -> 1782.89 | C6: ='Balance_Sheet (5 years)'!D29 -> 2665.99 | D6: ='Balance_Sheet (5 years)'!E29 -> 3149.76 | E6: ='Balance_Sheet (5 years)'!F29 -> 3502.98 | F6: =F3-F4+F5 -> 4349.3078 | G6: =G3-G4+G5 -> 5434.828 | H6: =H3-H4+H5 -> 6461.9744 | I6: =I3-I4+I5 -> 7758.8541 | J6: =J3-J4+J5 -> 9481.8865 | K6: =K3-K4+K5 -> 11537.325 | L6: =L3-L4+L5 -> 13905.539 | M6: =M3-M4+M5 -> 16833.612
A8: Assumptions
A9: Fiscal Year | B9: Mar-2021 | C9: Mar-2022 | D9: Mar-2023 | E9: 45352 | F9: Mar-2025 | G9: 46082 | H9: 46447 | I9: 46813 | J9: 47178 | K9: 47543 | L9: 47908 | M9: 48274
A10: D&A as a % of Beginning PP&E | B10: =B4/B3 -> 0.16078084 | C10: =C4/C3 -> 0.15097398 | D10: =D4/D3 -> 0.10594188 | E10: =E4/E3 -> 0.11106878 | F10: =F4/F3 -> 0.11421418 | G10: =AVERAGE(B10:F10) -> 0.12859593 | H10: =AVERAGE(C10:G10) -> 0.12215895 | I10: =AVERAGE(D10:H10) -> 0.11639595 | J10: =AVERAGE(E10:I10) -> 0.11848676 | K10: =AVERAGE(F10:J10) -> 0.11997035 | L10: =AVERAGE(G10:K10) -> 0.12112159 | M10: =AVERAGE(H10:L10) -> 0.11962672
A11: CapEx as a % of Beginning PP&E | B11: =B5/B3 -> 0.26635992 | C11: =C5/C3 -> 0.64629338 | D11: =D5/D3 -> 0.28740168 | E11: =E5/E3 -> 0.22321066 | F11: =AVERAGE(B11:E11) -> 0.35581641 | G11: =AVERAGE(C11:F11) -> 0.37818053 | H11: =AVERAGE(D11:G11) -> 0.31115232 | I11: =AVERAGE(E11:H11) -> 0.31708998 | J11: =AVERAGE(F11:I11) -> 0.34055981 | K11: =AVERAGE(G11:J11) -> 0.33674566 | L11: =AVERAGE(H11:K11) -> 0.32638694 | M11: =AVERAGE(I11:L11) -> 0.3301956

Sheet Risk-free_rate
B1: India's 10 years Government Bond Yield history
B3: Date | C3: Price | D3: Open | E3: High | F3: Low | G3: Change %
B4: 45717 | C4: 6.57 | D4: 6.73 | E4: 6.74 | F4: 6.57 | G4: -0.0223
B5: 45689 | C5: 6.72 | D5: 6.66 | E5: 6.72 | F5: 6.65 | G5: 0.0045
B6: 45658 | C6: 6.69 | D6: 6.78 | E6: 6.84 | F6: 6.67 | G6: -0.0104 | J6: Risk-free rate | K6: =AVERAGE(Table1[Price]) -> 6.9652417
B7: 45627 | C7: 6.76 | D7: 6.802 | E7: 6.807 | F7: 6.668 | G7: 0.0013
B8: 45597 | C8: 6.751 | D8: 6.831 | E8: 6.863 | F8: 6.739 | G8: -0.0132 | L8: =0.0697 -> 0.0697
B9: 45566 | C9: 6.841 | D9: 6.759 | E9: 6.875 | F9: 6.73 | G9: 0.0135
B10: 45536 | C10: 6.75 | D10: 6.877 | E10: 6.885 | F10: 6.706 | G10: -0.0165
B11: 45505 | C11: 6.863 | D11: 6.912 | E11: 6.919 | F11: 6.843 | G11: -0.0088
B12: 45474 | C12: 6.924 | D12: 7.023 | E12: 7.024 | F12: 6.91 | G12: -0.012
B13: 45444 | C13: 7.008 | D13: 6.955 | E13: 7.062 | F13: 6.945 | G13: 0.0031
B14: 45413 | C14: 6.986 | D14: 7.17 | E14: 7.173 | F14: 6.967 | G14: -0.029
B15: 45383 | C15: 7.195 | D15: 7.085 | E15: 7.242 | F15: 7.075 | G15: 0.0203
B16: 45352 | C16: 7.052 | D16: 7.062 | E16: 7.103 | F16: 7.006 | G16: -0.0037
B17: 45323 | C17: 7.078 | D17: 7.129 | E17: 7.14 | F17: 7.021 | G17: -0.0092
B18: 45292 | C18: 7.144 | D18: 7.207 | E18: 7.239 | F18: 7.134 | G18: -0.0045
B19: 45261 | C19: 7.176 | D19: 7.293 | E19: 7.298 | F19: 7.147 | G19: -0.0142
B20: 45231 | C20: 7.279 | D20: 7.376 | E20: 7.376 | F20: 7.194 | G20: -0.0098
... B123: 42095 | C123: 7.86 | D123: 7.722 | E123: 7.873 | F123: 7.711 | G123: 0.0158

Sheet Beta_Calculation
B1: Market Return (BSE500)
B2: Year | C2: Close | D2: Returns | G2: Bajaj Auto Ltd. - Beta Analysis - 2009-01-01-2025-08-10 - [INR-Crores]
B3: 2024 | C3: 35189.03 | D3: =(C3-C4)/C4 -> 0.1454658 | G3: BSE500 | H3: 0.77
B4: 2023 | C4: 30720.28 | D4: =(C4-C5)/C5 -> 0.24849852 | G4: NIFTY | H4: 0.73
B5: 2022 | C5: 24605.78 | D5: =(C5-C6)/C6 -> 0.033378691 | G5: Source : Ace Equity
B6: 2021 | C6: 23811 | D6: =(C6-C7)/C7 -> 0.30114043
B7: 2020 | C7: 18300.1 | D7: =(C7-C8)/C8 -> 0.16803383 | G7: Rm (Market return) | I7: =AVERAGE(D3:D27) -> 0.19864599
B8: 2019 | C8: 15667.44 | D8: =(C8-C9)/C9 -> 0.077511676
B9: 2018 | C9: 14540.39 | D9: =(C9-C10)/C10 -> -0.030817058
B10: 2017 | C10: 15002.73 | D10: =(C10-C11)/C11 -> 0.35938129
B11: 2016 | C11: 11036.44 | D11: =(C11-C12)/C12 -> 0.037823178
B12: 2015 | C12: 10634.22 | D12: =(C12-C13)/C13 -> -0.0081517532
B13: 2014 | C13: 10721.62 | D13: =(C13-C14)/C14 -> 0.36959049
B14: 2013 | C14: 7828.34 | D14: =(C14-C15)/C15 -> 0.032548667
B15: 2012 | C15: 7581.57 | D15: =(C15-C16)/C16 -> 0.31198994
B16: 2011 | C16: 5778.68 | D16: =(C16-C17)/C17 -> -0.27413184
B17: 2010 | C17: 7961.06 | D17: =(C17-C18)/C18 -> 0.16351493
B18: 2009 | C18: 6842.25 | D18: =(C18-C19)/C19 -> 0.9022895
B19: 2008 | C19: 3596.85 | D19: =(C19-C20)/C20 -> -0.58139316
... B26: 2001 | C26: 1005.82 | D26: =(C26-C27)/C27 -> -0.22905585
B27: 2000 | C27: 1304.66

Sheet Balance_Sheet (5 years)
A1: Particulars | B1: Mar-2021 | C1: Mar-2022 | D1: Mar-2023 | E1: Mar-2024 | F1: Mar-2025
A3: EQUITY AND LIABILITIES
A4: Share Capital | B4: 289.37 | C4: 289.37 | D4: 282.96 | E4: 279.18 | F4: 279.26
A5: Share Warrants & Outstandings | B5: 16.91 | C5: 32.27 | D5: 62.09 | E5: 102.46 | F5: 99.44
A6: Total Reserves | B6: 24895.98 | C6: 26347.16 | D6: 25080.81 | E6: 24478.86 | F6: 31768.24
A7: Shareholder's Funds | B7: 25202.26 | C7: 26668.8 | D7: 25425.86 | E7: 24860.5 | F7: 32146.94
A8: Long-Term Borrowings
A9: Secured Loans
A10: Unsecured Loans | B10: 121.46 | C10: 122.77 | D10: 124.23 | E10: 125.84 | F10: 127.64
A11: Deferred Tax Assets / Liabilities | B11: 522.14 | C11: 403.33 | D11: 345.15 | E11: 506.94 | F11: 1123.03
A12: Other Long Term Liabilities | B12: 39.15 | C12: 36.3 | D12: 33.54 | E12: 30.83 | F12: 28.09
A13: Long Term Trade Payables
A14: Long Term Provisions | B14: 1.98 | C14: 1.3 | D14: 0.87 | E14: 0.84 | F14: 0.45
A15: Total Non-Current Liabilities | B15: 684.73 | C15: 563.7 | D15: 503.79 | E15: 664.45 | F15: 1279.21
A16: Current Liabilities
A17: Trade Payables | B17: 4573.81 | C17: 3633.18 | D17: 4073.88 | E17: 5593.61 | F17: 6267.63
A18: Other Current Liabilities | B18: 892.88 | C18: 878.36 | D18: 934.47 | E18: 2083.4 | F18: 1455.46
A19: Short Term Borrowings | E19: 834.05 | F19: 800
A20: Short Term Provisions | B20: 176.52 | C20: 177.9 | D20: 189.69 | E20: 222.82 | F20: 479.66
A21: Total Current Liabilities | B21: 5643.21 | C21: 4689.44 | D21: 5198.04 | E21: 8733.88 | F21: 9002.75
A22: Liabilities as Held for Sale and Discontinued Operations
A23: Total Liabilities | B23: 31530.2 | C23: 31921.94 | D23: 31127.69 | E23: 34258.83 | F23: 42428.9
A24: ASSETS
A25: Non-Current Assets
A26: Gross Block | B26: 4274.64 | C26: 4561.56 | D26: 5434.8 | E26: 6162.88 | F26: 6882.07
A27: Less: Accumulated Depreciation | B27: 2662.01 | C27: 2778.67 | D27: 2768.81 | E27: 3013.12 | F27: 3379.09
A28: Less: Impairment of Assets
A29: Net Block | B29: 1612.63 | C29: 1782.89 | D29: 2665.99 | E29: 3149.76 | F29: 3502.98
A30: Lease Adjustment A/c
A31: Capital Work in Progress | B31: 15.98 | C31: 76.82 | D31: 81.92 | E31: 24.29 | F31: 26.02
A32: Intangible assets under development | E32: 3.2 | F32: 2.24
A33: Pre-operative Expenses pending
A34: Assets in transit | B34: 52.3 | C34: 51.13 | D34: 50.02 | E34: 48.9 | F34: 47.78
A35: Non Current Investments | B35: 14602.84 | C35: 18849.63 | D35: 18503.96 | E35: 19613.02 | F35: 22986.78
A36: Long Term Loans & Advances | B36: 1054.77 | C36: 1119.52 | D36: 954.35 | E36: 1035.19 | F36: 2416.91
A37: Other Non Current Assets | B37: 16.55 | C37: 47.48 | D37: 1.05 | E37: 19.11 | F37: 18.88
A38: Total Non-Current Assets | B38: 17355.07 | C38: 21927.47 | D38: 22257.29 | E38: 23893.47 | F38: 29001.59
A39: Current Assets Loans & Advances
A40: Currents Investments | B40: 8028.11 | C40: 4969.13 | D40: 4419.37 | E40: 3837.98 | F40: 5583.45
A41: Inventories | B41: 1493.89 | C41: 1230.51 | D41: 1397.9 | E41: 1695.62 | F41: 1957.9
...

Sheet Income_Statement (5 years)
A1: Particulars | B1: Mar-2021 | C1: Mar-2022 | D1: Mar-2023 | E1: Mar-2024 | F1: Mar-2025
A3: No of Months | B3: 12 | C3: 12 | D3: 12 | E3: 12 | F3: 12
A4: INCOME :
A5: Gross Sales | B5: 27925.02 | C5: 33387.61 | D5: 36737.22 | E5: 45056.43 | F5: 50378.56
A6: Less: Inter divisional transfers
A7: Less: Sales Returns | B7: 183.94 | C7: 242.9 | D7: 309.62 | E7: 371.2 | F7: 368.25
A8: Less: Excise / GST
A9: Net Sales | B9: 27741.08 | C9: 33144.71 | D9: 36427.6 | E9: 44685.23 | F9: 50010.31
A10: EXPENDITURE :
A11: Increase/Decrease in Stock | B11: -219.48 | C11: 187.96 | D11: -98.11 | E11: -70.45 | F11: 35.18
A12: Raw Material Consumed | B12: 19829.13 | C12: 24141.86 | D12: 26152.86 | E12: 31813.89 | F12: 35302.26
A13: Power & Fuel Cost | B13: 91.34 | C13: 108.01 | D13: 122.51 | E13: 147.8 | F13: 176.94
A14: Employee Cost | B14: 1285.96 | C14: 1358.8 | D14: 1444.9 | E14: 1537.56 | F14: 1579.44
A15: Other Manufacturing Expenses | B15: 700.77 | C15: 939.67 | D15: 900.44 | E15: 932.97 | F15: 1101.24
A16: General and Administration Expenses | B16: 62.87 | C16: 61.57 | D16: 89.77 | E16: 107.51 | F16: 117.62
A17: Selling and Distribution Expenses | B17: 494.81 | C17: 480.91 | D17: 584.53 | E17: 654.22 | F17: 739.62
A18: Miscellaneous Expenses | B18: 585.04 | C18: 642.71 | D18: 711.38 | E18: 826.8 | F18: 913.84
A19: Less: Expenses Capitalised | B19: 12.27 | C19: 13.31 | D19: 27.82 | E19: 47.53 | F19: 49.67
A20: Total Expenditure | B20: 22818.17 | C20: 27908.18 | D20: 29880.46 | E20: 35902.77 | F20: 39916.47
A21: Operating Profit (Excl OI) | B21: 4922.91 | C21: 5236.53 | D21: 6547.14 | E21: 8782.46 | F21: 10093.84
A22: Other Income | B22: 1282.03 | C22: 1231.35 | D22: 1183.42 | E22: 1442.89 | F22: 1425.86
... A27: Profit Before Taxation & Exceptional Items | B27: 5939 | C27: 6190.05 | D27: 7408.64 | E27: 9822.01 | F27: 11051.89
A28: Share of Profit/Loss of JV & Associates
A29: Exceptional Income / Expenses | C29: 315.28
A30: Profit Before Tax | B30: 5939 | C30: 6505.33 | D30: 7408.64 | E30: 9822.01 | F30: 11051.89
A31: Provision for Tax | B31: 1384.41 | C31: 1486.46 | D31: 1781.04 | E31: 2343.22 | F31: 2900.47
A32: Profit After Tax | B32: 4554.59 | C32: 5018.87 | D32: 5627.6 | E32: 7478.79 | F32: 8151.42
A33: Discontinued Operations
A34: Profit Before Tax from Discontinued Operations
A35: Tax from Discontinued Operations
A36: Profit After Tax from Discontinued Operations
A37: Extra items
A38: Adjustments to PAT
A39: Profit Balance B/F | B39: 14750.44 | C39: 18861.25 | D39: 19340.4 | E39: 17821.4 | F39: 16416.32
A40: Appropriations | B40: 19305.03 | C40: 23880.12 | D40: 24968 | E40: 25300.19 | F40: 24567.74
A41: Equity Dividend % | B41: 1400 | C41: 1400 | D41: 1400 | E41: 800 | F41: 2100
A42: Earnings Per Share(Calculated) | B42: 157.4 | C42: 173.44 | D42: 198.88 | E42: 267.88 | F42: 291.89
A43: Adjusted EPS | B43: 157.4 | C43: 173.44 | D43: 198.88 | E43: 267.88 | F43: 291.89
A44: EPS - Basic (Reported) | B44: 157.5 | C44: 173.6 | D44: 197.3 | E44: 264.6 | F44: 292.1
A45: EPS - Diluted (Reported) | B45: 157.5 | C45: 173.6 | D45: 197.3 | E45: 264.3 | F45: 291.5

Sheet Cash_Flows (5 years)
A1: Particulars | B1: Mar-2021 | C1: Mar-2022 | D1: Mar-2023 | E1: Mar-2024 | F1: Mar-2025
A3: Profit Before Tax | B3: 5939 | C3: 6505.33 | D3: 7408.64 | E3: 9822.01 | F3: 11051.89
A4: Adjustment | B4: -974.64 | C4: -1196.79 | D4: -701.37 | E4: -963.35 | F4: -861.87
A5: Changes In working Capital | B5: -510.81 | C5: 600.57 | D5: 723.03 | E5: 1002.23 | F5: -242.94
A6: Cash Flow after changes in Working Capital | B6: 4453.55 | C6: 5909.11 | D6: 7430.3 | E6: 9860.89 | F6: 9947.08
A7: Interest Paid
A8: Tax Paid | B8: -1339.69 | C8: -1701.54 | D8: -1918.41 | E8: -2382.62 | F8: -2680.35
A9: Other Direct Expenses paid
A10: Extra & Other Item
A11: Cash From Operating Activities | B11: 3113.86 | C11: 4207.57 | D11: 5511.89 | E11: 7478.27 | F11: 7266.73
A12: Cash Flow from Investing Activities | B12: -2865.35 | C12: -95.95 | D12: 1333.81 | E12: -139.22 | F12: -3640.98
A13: Cash from Financing Activities | B13: -19.52 | C13: -4056.33 | D13: -7178.86 | E13: -7110.05 | F13: -3254.23
A14: Net Cash Inflow / Outflow | B14: 228.99 | C14: 55.29 | D14: -333.16 | E14: 229 | F14: 371.52
A15: Opening Cash & Cash Equivalents | B15: 277.33 | C15: 505.13 | D15: 563.97 | E15: 219.42 | F15: 448.61
A16: Cash & Cash Equivalent on Amalgamation / Take over / Merger
A17: Cash & Cash Equivalent of Subsidiaries under liquidations
A18: Translation adj. on reserves / op cash balances frgn subsidiaries
A19: Effect of Foreign Exchange Fluctuations | B19: -1.19 | C19: 3.55 | D19: -11.39 | E19: 0.19 | F19: -6.71
A20: Closing Cash & Cash Equivalent | B20: 505.13 | C20: 563.97 | D20: 219.42 | E20: 448.61 | F20: 813.42

Sheet Balance_Sheet
A1: Bajaj Auto Ltd. - Balance Sheet - Standalone-Abridged-Actual - [INR-Crores]
A2: Particulars | B2: Mar-2025 | C2: Mar-2024 | D2: Mar-2023 | E2: Mar-2022 | F2: Mar-2021 | G2: Mar-2020 | H2: Mar-2019 | I2: Mar-2018 | J2: Mar-2017 | K2: Mar-2016 | L2: Mar-2015 | M2: Mar-2014 | N2: Mar-2013 | O2: Mar-2012 | P2: Mar-2011 | Q2: Mar-2010 | R2: Mar-2009 | S2: Mar-2008
A4: EQUITY AND LIABILITIES
A5: Share Capital | B5: 279.26 | C5: 279.18 | D5: 282.96 | E5: 289.37 | F5: 289.37 | G5: 289.37 | H5: 289.37 | I5: 289.37 | J5: 289.37 | K5: 289.37 | L5: 289.37 | M5: 289.37 | N5: 289.37 | O5: 289.37 | P5: 289.37 | Q5: 144.68 | R5: 144.68 | S5: 144.68
A6: Share Warrants & Outstandings | B6: 99.44 | C6: 102.46 | D6: 62.09 | E6: 32.27 | F6: 16.91 | G6: 10.01 | H6: 0 | I6: 0 | J6: 0 | K6: 0 | L6: 0 | M6: 0 | N6: 0 | O6: 0 | P6: 0 | Q6: 0 | R6: 0 | S6: 0
A7: Total Reserves | B7: 31768.24 | C7: 24478.86 | D7: 25080.81 | E7: 26347.16 | F7: 24895.98 | G7: 19626.11 | H7: 21490.53 | I7: 18814.49 | J7: 16744.76 | K7: 12977.18 | L7: 10402.78 | M7: 9318.65 | N7: 7612.58 | O7: 5751.7 | P7: 4620.85 | Q7: 2783.66 | R7: 1725.01 | S7: 1442.91
A8: Shareholder's Funds | B8: 32146.94 | C8: 24860.5 | D8: 25425.86 | E8: 26668.8 | F8: 25202.26 | G8: 19925.49 | H8: 21779.9 | I8: 19103.86 | J8: 17034.13 | K8: 13266.55 | L8: 10692.15 | M8: 9608.02 | N8: 7901.95 | O8: 6041.07 | P8: 4910.22 | Q8: 2928.34 | R8: 1869.69 | S8: 1587.59
A9: Long-Term Borrowings
A10: Secured Loans | Q10: 12.98 | S10: 6.95
A11: Unsecured Loans | B11: 127.64 | C11: 125.84 | D11: 124.23 | E11: 122.77 | F11: 121.46 | G11: 125.59 | H11: 124.52 | I11: 120.77 | J11: 119.9 | K11: 117.86 | L11: 111.77 | M11: 57.74 | N11: 71.27 | O11: 97.48 | P11: 133.88 | Q11: 1325.6 | R11: 1570 | S11: 1327.39
A12: Deferred Tax Assets / Liabilities | B12: 1123.03 | C12: 506.94 | D12: 345.15 | E12: 403.33 | F12: 522.14 | G12: 346.38 | H12: 542.66 | I12: 323.42 | J12: 313.62 | K12: 202.8 | L12: 141.58 | M12: 143.18 | N12: 115.1 | O12: 48.44 | P12: 29.71 | Q12: 1.69 | R12: 4.19 | S12: 10.98
A13: Other Long Term Liabilities | B13: 28.09 | C13: 30.83 | D13: 33.54 | E13: 36.3 | F13: 39.15 | G13: 42.13 | H13: 45.07 | I13: 47.96 | J13: 56.53 | K13: 70.73 | L13: 57.59 | M13: 87.43 | N13: 117.94 | O13: 148.87 | P13: 181.53
A14: Long Term Trade Payables | N14: 4.12 | O14: 8.2 | P14: 12.18
A15: Long Term Provisions | B15: 0.45 | C15: 0.84 | D15: 0.87 | E15: 1.3 | F15: 1.98 | G15: 80.5 | H15: 14.56 | I15: 112.19 | J15: 78.13 | K15: 47.57 | L15: 82.44 | M15: 120.99 | N15: 134.61 | O15: 111.85 | P15: 124.54
A16: Total Non-Current Liabilities | B16: 1279.21 | C16: 664.45 | D16: 503.79 | E16: 563.7 | F16: 684.73 | G16: 594.6 | H16: 726.81 | I16: 604.34 | J16: 568.18 | K16: 438.96 | L16: 393.38 | M16: 409.34 | N16: 443.04 | O16: 414.84 | P16: 481.84 | Q16: 1340.27 | R16: 1574.19 | S16: 1345.32
A17: Current Liabilities
A18: Trade Payables | B18: 6267.63 | C18: 5593.61 | D18: 4073.88 | E18: 3633.18 | F18: 4573.81 | G18: 3199.7 | H18: 3786.73 | I18: 3244.32 | J18: 2235.73 | K18: 2027.04 | L18: 1760.53 | M18: 2111.4 | N18: 1979.61 | O18: 1957.79 | P18: 1789.26 | Q18: 1571.2 | R18: 799.98 | S18: 878.75
A19: Other Current Liabilities | B19: 1455.46 | C19: 2083.4 | D19: 934.47 | E19: 878.36 | F19: 892.88 | G19: 879.8 | H19: 930.59 | I19: 725.63 | J19: 840.18 | K19: 606.63 | L19: 806.69 | M19: 766.14 | N19: 546.16 | O19: 604.33 | P19: 477.11 | Q19: 455.05 | R19: 413.43 | S19: 164.5
A20: Short Term Borrowings | B20: 800 | C20: 834.05 | P20: 157.84
A21: Short Term Provisions | B21: 479.66 | C21: 222.82 | D21: 189.69 | E21: 177.9 | F21: 176.52 | G21: 173.71 | H21: 156.36 | I21: 141.34 | J21: 136.67 | K21: 147.32 | L21: 1909.57 | M21: 1852.7 | N21: 1607.86 | O21: 2066.05 | P21: 1431.26 | Q21: 3665.84 | R21: 1224.15 | S21: 834.04
A22: Total Current Liabilities | B22: 9002.75 | C22: 8733.88 | D22: 5198.04 | E22: 4689.44 | F22: 5643.21 | G22: 4253.21 | H22: 4873.68 | I22: 4111.29 | J22: 3212.58 | K22: 2780.99 | L22: 4476.79 | M22: 4730.24 | N22: 4133.63 | O22: 4628.17 | P22: 3855.47 | Q22: 5692.09 | R22: 2437.56 | S22: 1877.29
A23: Liabilities as Held for Sale and Discontinued Operations
A24: Total Liabilities | B24: 42428.9 | C24: 34258.83 | D24: 31127.69 | E24: 31921.94 | F24: 31530.2 | G24: 24773.3 | H24: 27380.39 | I24: 23819.49 | J24: 20814.89 | K24: 16486.5 | L24: 15562.32 | M24: 14747.6 | N24: 12478.62 | O24: 11084.08 | P24: 9247.53 | Q24: 9960.7 | R24: 5881.44 | S24: 4810.2
A25: ASSETS
A26: Non-Current Assets
A27: Gross Block | B27: 6882.07 | C27: 6162.88 | D27: 5434.8 | E27: 4561.56 | F27: 4274.64 | G27: 4087.66 | H27: 4225.97 | I27: 4449.14 | J27: 4533.21 | K27: 4434.89 | L27: 4100.91 | M27: 4077.04 | N27: 3828.85 | O27: 3396.06 | P27: 3395.16 | Q27: 3379.25 | R27: 3350.2 | S27: 2994.68
A28: Less: Accumulated Depreciation | B28: 3379.09 | C28: 3013.12 | D28: 2768.81 | E28: 2778.67 | F28: 2662.01 | G28: 2442.54 | H28: 2517.53 | I28: 2627.92 | J28: 2589.95 | K28: 2409.22 | L28: 2183.67 | M28: 2071 | N28: 2024.42 | O28: 1914.33 | P28: 1912.45 | Q28: 1899.66 | R28: 1807.91 | S28: 1726.07
A29: Less: Impairment of Assets
A30: Net Block | B30: 3502.98 | C30: 3149.76 | D30: 2665.99 | E30: 1782.89 | F30: 1612.63 | G30: 1645.12 | H30: 1708.44 | I30: 1821.22 | J30: 1943.26 | K30: 2025.67 | L30: 1917.24 | M30: 2006.04 | N30: 1804.43 | O30: 1481.73 | P30: 1482.71 | Q30: 1479.59 | R30: 1542.29 | S30: 1268.61
A31: Lease Adjustment A/c
A32: Capital Work in Progress | B32: 26.02 | C32: 24.29 | D32: 81.92 | E32: 76.82 | F32: 15.98 | G32: 46.54 | H32: 11.54 | I32: 11.15 | J32: 10.64 | K32: 26.89 | L32: 101.72 | M32: 32.55 | N32: 223.29 | O32: 11.77 | P32: 69.86 | Q32: 41.52 | R32: 22.06 | S32: 34.74
A33: Intangible assets under development | B33: 2.24 | C33: 3.2 | G33: 13.65 | H33: 36.48 | I33: 45.32 | J33: 31.53 | K33: 25.35 | L33: 153.22 | M33: 111.51 | N33: 70.26 | O33: 29.88
A34: Pre-operative Expenses pending
A35: Assets in transit | B35: 47.78 | C35: 48.9 | D35: 50.02 | E35: 51.13 | F35: 52.3 | G35: 53.9 | H35: 55.5 | I35: 57.11 | J35: 58.53 | K35: 60.43
A36: Non Current Investments | B36: 22986.78 | C36: 19613.02 | D36: 18503.96 | E36: 18849.63 | F36: 14602.84 | G36: 15416.2 | H36: 17582.88 | I36: 11822.89 | J36: 8681.39 | K36: 8940.65 | L36: 3352.76 | M36: 6259.93 | N36: 3719.15 | O36: 3786.21 | P36: 4035.08 | Q36: 2296.32 | R36: 1465.15 | S36: 1743.21
A37: Long Term Loans & Advances | B37: 2416.91 | C37: 1035.19 | D37: 954.35 | E37: 1119.52 | F37: 1054.77 | G37: 997.8 | H37: 922.87 | I37: 826.15 | J37: 698.15 | K37: 682.24 | L37: 511.07 | M37: 719.92 | N37: 462.39 | O37: 601.28 | P37: 227.59
A38: Other Non Current Assets | B38: 18.88 | C38: 19.11 | D38: 1.05 | E38: 47.48 | F38: 16.55 | G38: 3.13 | H38: 0.02 | I38: 0.02 | J38: 0.02 | K38: 0.02 | L38: 0.04 | M38: 1.02 | N38: 1.02 | O38: 1.02 | P38: 401.14
A39: Total Non-Current Assets | B39: 29001.59 | C39: 23893.47 | D39: 22257.29 | E39: 21927.47 | F39: 17355.07 | G39: 18176.34 | H39: 20317.73 | I39: 14583.86 | J39: 11423.52 | K39: 11761.25 | L39: 6036.05 | M39: 9130.97 | N39: 6280.54 | O39: 5911.89 | P39: 6216.38 | Q39: 3817.43 | R39: 3029.5 | S39: 3046.56
A40: Current Assets Loans & Advances
A41: Currents Investments | B41: 5583.45 | C41: 3837.98 | D41: 4419.37 | E41: 4969.13 | F41: 8028.11 | G41: 2779.75 | H41: 1576.48 | I41: 5765.41 | J41: 6050.08 | K41: 1319.94 | L41: 5800.56 | M41: 2289.7 | N41: 2711.33 | O41: 1096.6 | P41: 686.83 | Q41: 1725.2 | R41: 343.37 | S41: 113.93
...

Sheet Income_Statement
A1: Bajaj Auto Ltd. - Profit And Loss - Standalone-Abridged-Actual-Reported - [INR-Crores]
A2: Particulars | B2: Mar-2025 | C2: Mar-2024 | D2: Mar-2023 | E2: Mar-2022 | F2: Mar-2021 | G2: Mar-2020 | H2: Mar-2019 | I2: Mar-2018 | J2: Mar-2017 | K2: Mar-2016 | L2: Mar-2015 | M2: Mar-2014 | N2: Mar-2013 | O2: Mar-2012 | P2: Mar-2011 | Q2: Mar-2010 | R2: Mar-2009 | S2: Mar-2008
A4: No of Months | B4: 12 | C4: 12 | D4: 12 | E4: 12 | F4: 12 | G4: 12 | H4: 12 | I4: 12 | J4: 12 | K4: 12 | L4: 12 | M4: 12 | N4: 12 | O4: 12 | P4: 12 | Q4: 12 | R4: 12 | S4: 12
A5: INCOME :
A6: Gross Sales | B6: 50378.56 | C6: 45056.43 | D6: 36737.22 | E6: 33387.61 | F6: 27925.02 | G6: 30103.24 | H6: 30511.98 | I6: 25766.24 | J6: 23088.03 | K6: 23883.2 | L6: 22521.29 | M6: 21158.91 | N6: 21126.16 | O6: 20475.74 | P6: 17331.64 | Q6: 12118.08 | R6: 9049.66 | S6: 9689.95
A7: Less: Inter divisional transfers
A8: Less: Sales Returns | B8: 368.25 | C8: 371.2 | D8: 309.62 | E8: 242.9 | F8: 183.94 | G8: 184.59 | H8: 154.41 | I8: 148.98
A9: Less: Excise / GST | I9: 398.34 | J9: 1321.35 | K9: 1296.68 | L9: 909.28 | M9: 1009.4 | N9: 1128.91 | O9: 946.76 | P9: 933.41 | Q9: 609.58 | R9: 612.72 | S9: 1026.66
A10: Net Sales | B10: 50010.31 | C10: 44685.23 | D10: 36427.6 | E10: 33144.71 | F10: 27741.08 | G10: 29918.65 | H10: 30357.57 | I10: 25218.92 | J10: 21766.68 | K10: 22586.52 | L10: 21612.01 | M10: 20149.51 | N10: 19997.25 | O10: 19528.98 | P10: 16398.23 | Q10: 11508.5 | R10: 8436.94 | S10: 8663.29
A11: EXPENDITURE :
A12: Increase/Decrease in Stock | B12: 35.18 | C12: -70.45 | D12: -98.11 | E12: 187.96 | F12: -219.48 | G12: -63.01 | H12: -56.42 | I12: 9.68 | J12: -43.68 | K12: 63.45 | L12: -46.05 | M12: -27.03 | N12: 30.27 | O12: -81.82 | P12: -81.49 | Q12: -49.48 | R12: 21.84 | S12: -65
A13: Raw Material Consumed | B13: 35302.26 | C13: 31813.89 | D13: 26152.86 | E13: 24141.86 | F13: 19829.13 | G13: 21071.29 | H13: 21854.1 | I13: 17400.41 | J13: 14667.83 | K13: 14993.41 | L13: 14907.36 | M13: 13895.57 | N13: 14382.57 | O13: 14196.69 | P13: 11880.3 | Q13: 8119.92 | R13: 6441.63 | S13: 6685.37
A14: Power & Fuel Cost | B14: 176.94 | C14: 147.8 | D14: 122.51 | E14: 108.01 | F14: 91.34 | G14: 116.57 | H14: 115.01 | I14: 100.26 | J14: 96.46 | K14: 120.66 | L14: 114.7 | M14: 106.16 | N14: 121.33 | O14: 101.85 | P14: 86.61 | Q14: 70.35 | R14: 60.89 | S14: 69.2
A15: Employee Cost | B15: 1579.44 | C15: 1537.56 | D15: 1444.9 | E15: 1358.8 | F15: 1285.96 | G15: 1389.21 | H15: 1255.4 | I15: 1069.09 | J15: 997.07 | K15: 883.42 | L15: 865.24 | M15: 696.48 | N15: 611.76 | O15: 515.39 | P15: 476.78 | Q15: 396.64 | R15: 351.63 | S15: 339.81
A16: Other Manufacturing Expenses | B16: 1101.24 | C16: 932.97 | D16: 900.44 | E16: 939.67 | F16: 700.77 | G16: 832.27 | H16: 753.47 | I16: 652.8 | J16: 650.4 | K16: 749.06 | L16: 733.99 | M16: 601.17 | N16: 590.69 | O16: 575.01 | P16: 460.88 | Q16: 390.07 | R16: 381.52 | S16: 374.08
A17: General and Administration Expenses | B17: 117.62 | C17: 107.51 | D17: 89.77 | E17: 61.57 | F17: 62.87 | G17: 109.87 | H17: 96.18 | I17: 81.68 | J17: 92.55 | K17: 112.7 | L17: 102.91 | M17: 94.54 | N17: 86.32 | O17: 70.05 | P17: 63.82 | Q17: 29.58 | R17: 29.33 | S17: 19.53
A18: Selling and Distribution Expenses | B18: 739.62 | C18: 654.22 | D18: 584.53 | E18: 480.91 | F18: 494.81 | G18: 781.55 | H18: 728.22 | I18: 671.38 | J18: 506.59 | K18: 527.96 | L18: 505.93 | M18: 404.36 | N18: 325.47 | O18: 270.53 | P18: 193.84 | Q18: 220.04 | R18: 179.22 | S18: 204.24
A19: Miscellaneous Expenses | B19: 913.84 | C19: 826.8 | D19: 711.38 | E19: 642.71 | F19: 585.04 | G19: 614.64 | H19: 449.23 | I19: 619.69 | J19: 400.62 | K19: 370.94 | L19: 375.93 | M19: 370.38 | N19: 332.6 | O19: 248.7 | P19: 180.55 | Q19: 167.15 | R19: 167.56 | S19: 148.45
A20: Less: Expenses Capitalised | B20: 49.67 | C20: 47.53 | D20: 27.82 | E20: 13.31 | F20: 12.27 | G20: 29.97 | H20: 30.1 | I20: 24.07 | J20: 22.27 | K20: 17.02 | L20: 60.05 | M20: 64.9 | N20: 62.85 | O20: 49.43 | P20: 16.66 | Q20: 15.67 | R20: 14.42 | S20: 23.04
A21: Total Expenditure | B21: 39916.47 | C21: 35902.77 | D21: 29880.46 | E21: 27908.18 | F21: 22818.17 | G21: 24822.42 | H21: 25165.09 | I21: 20580.92 | J21: 17345.57 | K21: 17804.58 | L21: 17499.96 | M21: 16076.73 | N21: 16418.16 | O21: 15846.97 | P21: 13244.63 | Q21: 9328.6 | R21: 7619.2 | S21: 7752.64
A22: Operating Profit (Excl OI) | B22: 10093.84 | C22: 8782.46 | D22: 6547.14 | E22: 5236.53 | F22: 4922.91 | G22: 5096.23 | H22: 5192.48 | I22: 4638 | J22: 4421.11 | K22: 4781.94 | L22: 4112.05 | M22: 4072.78 | N22: 3579.09 | O22: 3682.01 | P22: 3153.6 | Q22: 2179.9 | R22: 817.74 | S22: 910.65
A23: Other Income | B23: 1425.86 | C23: 1442.89 | D23: 1183.42 | E23: 1231.35 | F23: 1282.03 | G23: 1733.56 | H23: 1438.85 | I23: 1492.68 | J23: 1223.21 | K23: 1073.59 | L23: 586.92 | M23: 739.37 | N23: 854.45 | O23: 646.02 | P23: 594.13 | Q23: 535.16 | R23: 496.25 | S23: 505.56
... A28: Profit Before Taxation & Exceptional Items | B28: 11051.89 | C28: 9822.01 | D28: 7408.64 | E28: 6190.05 | F28: 5939 | G28: 6580.2 | H28: 6361.16 | I28: 5814.57 | J28: 5335.63 | K28: 5547.32 | L28: 4425.08 | M28: 4632.05 | N28: 4266.23 | O28: 4160.17 | P28: 3623.2 | Q28: 2572.63 | R28: 1163.19 | S28: 1237.09
A29: Share of Profit/Loss of JV & Associates
A30: Exceptional Income / Expenses | E30: 315.28 | H30: 342 | I30: -32 | L30: -340.29 | O30: -134 | P30: 724.55 | Q30: -161.5 | R30: -205.1 | S30: -102.36
A31: Profit Before Tax | B31: 11051.89 | C31: 9822.01 | D31: 7408.64 | E31: 6505.33 | F31: 5939 | G31: 6580.2 | H31: 6703.16 | I31: 5782.57 | J31: 5335.63 | K31: 5547.32 | L31: 4084.79 | M31: 4632.05 | N31: 4266.23 | O31: 4026.17 | P31: 4347.75 | Q31: 2411.13 | R31: 958.09 | S31: 1134.73
A32: Provision for Tax | B32: 2900.47 | C32: 2343.22 | D32: 1781.04 | E32: 1486.46 | F32: 1384.41 | G32: 1480.22 | H32: 2027.98 | I32: 1714.47 | J32: 1508.07 | K32: 1617.65 | L32: 1271.05 | M32: 1388.73 | N32: 1222.66 | O32: 1022.12 | P32: 1008.02 | Q32: 707.5 | R32: 301.61 | S32: 378.78
A33: Profit After Tax | B33: 8151.42 | C33: 7478.79 | D33: 5627.6 | E33: 5018.87 | F33: 4554.59 | G33: 5099.98 | H33: 4675.18 | I33: 4068.1 | J33: 3827.56 | K33: 3929.67 | L33: 2813.74 | M33: 3243.32 | N33: 3043.57 | O33: 3004.05 | P33: 3339.73 | Q33: 1703.63 | R33: 656.48 | S33: 755.95
A34: Discontinued Operations
A35: Profit Before Tax from Discontinued Operations
A36: Tax from Discontinued Operations
A37: Profit After Tax from Discontinued Operations
A38: Extra items | Q38: 0 | R38: 0 | S38: 0
A39: Adjustments to PAT | Q39: -3.52 | R39: -1.98 | S39: -0.17
A40: Profit Balance B/F | B40: 16416.32 | C40: 17821.4 | D40: 19340.4 | E40: 18861.25 | F40: 14750.44 | G40: 16451.58 | H40: 14321.65 | I40: 12562.56 | J40: 9305.17 | K40: 9206.96 | L40: 6150.45 | M40: 4920.26 | N40: 3705.14 | O40: 2515.48 | P40: 854.99
A41: Appropriations | B41: 24567.74 | C41: 25300.19 | D41: 24968 | E41: 23880.12 | F41: 19305.03 | G41: 21551.56 | H41: 18996.83 | I41: 16630.66 | J41: 13132.73 | K41: 13136.63 | L41: 8964.19 | M41: 8163.58 | N41: 6748.71 | O41: 5519.53 | P41: 4194.72 | Q41: 1700.11 | R41: 654.5 | S41: 755.78
A42: Equity Dividend % | B42: 2100 | C42: 800 | D42: 1400 | E42: 1400 | F42: 1400 | G42: 1200 | H42: 600 | I42: 600 | J42: 550 | K42: 550 | L42: 500 | M42: 500 | N42: 450 | O42: 450 | P42: 400 | Q42: 400 | R42: 220 | S42: 200
A43: Earnings Per Share(Calculated) | B43: 291.89 | C43: 267.88 | D43: 198.88 | E43: 173.44 | F43: 157.4 | G43: 176.24 | H43: 161.56 | I43: 140.58 | J43: 132.27 | K43: 135.8 | L43: 97.24 | M43: 112.08 | N43: 105.18 | O43: 103.81 | P43: 115.41 | Q43: 117.75 | R43: 45.37 | S43: 52.25
A44: Adjusted EPS | B44: 291.89 | C44: 267.88 | D44: 198.88 | E44: 173.44 | F44: 157.4 | G44: 176.24 | H44: 161.56 | I44: 140.58 | J44: 132.27 | K44: 135.8 | L44: 97.24 | M44: 112.08 | N44: 105.18 | O44: 103.81 | P44: 115.41 | Q44: 58.88 | R44: 22.69 | S44: 26.12
A45: EPS - Basic (Reported) | B45: 292.1 | C45: 264.6 | D45: 197.3 | E45: 173.6 | F45: 157.5 | G45: 176.3 | H45: 161.6 | I45: 140.6 | J45: 132.3 | K45: 135.8 | L45: 97.2 | M45: 112.1 | N45: 105.2 | O45: 103.8 | P45: 115.4 | R45: 45.2 | S45: 54.2
...

Sheet Cash_Flows
A1: Bajaj Auto Ltd. - Cash Flow - Standalone-Abridged-Actual - [INR-Crores]
A2: Particulars | B2: Mar-2025 | C2: Mar-2024 | D2: Mar-2023 | E2: Mar-2022 | F2: Mar-2021 | G2: Mar-2020 | H2: Mar-2019 | I2: Mar-2018 | J2: Mar-2017 | K2: Mar-2016 | L2: Mar-2015 | M2: Mar-2014 | N2: Mar-2013 | O2: Mar-2012 | P2: Mar-2011 | Q2: Mar-2010 | R2: Mar-2009 | S2: Mar-2008
A4: Profit Before Tax | B4: 11051.89 | C4: 9822.01 | D4: 7408.64 | E4: 6505.33 | F4: 5939 | G4: 6580.2 | H4: 6703.16 | I4: 5782.57 | J4: 5335.63 | K4: 5547.32 | L4: 4084.79 | M4: 4632.05 | N4: 4266.23 | O4: 4026.17 | P4: 4347.75 | Q4: 2411.13 | R4: 958.09
A5: Adjustment | B5: -861.87 | C5: -963.35 | D5: -701.37 | E5: -1196.79 | F5: -974.64 | G5: -1417.04 | H5: -1450.93 | I5: -858.96 | J5: -719.61 | K5: -619.07 | L5: -38.29 | M5: -176.28 | N5: -371.16 | O5: -16.3 | P5: -938.26 | Q5: 176.12 | R5: 250.15
A6: Changes In working Capital | B6: -242.94 | C6: 1002.23 | D6: 723.03 | E6: 600.57 | F6: -510.81 | G6: 376.26 | H6: -798.36 | I6: 1022.26 | J6: 225.76 | K6: 548.03 | L6: -613.78 | M6: 403.85 | N6: -521.3 | O6: 331.57 | P6: -821.52 | Q6: 849.75 | R6: -474.41
A7: Cash Flow after changes in Working Capital | B7: 9947.08 | C7: 9860.89 | D7: 7430.3 | E7: 5909.11 | F7: 4453.55 | G7: 5539.42 | H7: 4453.87 | I7: 5945.87 | J7: 4841.78 | K7: 5476.28 | L7: 3432.72 | M7: 4859.62 | N7: 3373.77 | O7: 4341.44 | P7: 2587.97 | Q7: 3437 | R7: 733.83
A8: Interest Paid
A9: Tax Paid | B9: -2680.35 | C9: -2382.62 | D9: -1918.41 | E9: -1701.54 | F9: -1339.69 | G9: -1677.66 | H9: -1964.34 | I9: -1685.08 | J9: -1502.58 | K9: -1819.47 | L9: -1285.4 | M9: -1313.91 | N9: -1239.4 | O9: -1148.27 | P9: -974.25 | Q9: -699.89 | R9: -321.26
A10: Other Direct Expenses paid
A11: Extra & Other Item
A12: Cash From Operating Activities | B12: 7266.73 | C12: 7478.27 | D12: 5511.89 | E12: 4207.57 | F12: 3113.86 | G12: 3861.76 | H12: 2489.53 | I12: 4260.79 | J12: 3339.2 | K12: 3656.81 | L12: 2147.32 | M12: 3545.71 | N12: 2134.37 | O12: 3193.17 | P12: 1613.72 | Q12: 2737.11 | R12: 412.57
A13: Cash Flow from Investing Activities | B13: -3640.98 | C13: -139.22 | D13: 1333.81 | E13: -95.95 | F13: -2865.35 | G13: 1754.54 | H13: -244.08 | I13: -1918.02 | J13: -3688.31 | K13: -18.83 | L13: -414.35 | M13: -2141.49 | N13: -1277.76 | O13: -681.91 | P13: -623.19 | Q13: -2163.62 | R13: -208.74
A14: Cash from Financing Activities | B14: -3254.23 | C14: -7110.05 | D14: -7178.86 | E14: -4056.33 | F14: -19.52 | G14: -6246.51 | H14: -2074.05 | I14: -1885.26 | J14: -190.09 | K14: -3384.08 | L14: -1644.18 | M14: -1468.22 | N14: -1479.08 | O14: -1564.38 | P14: -861.99 | Q14: -608.95 | R14: -123.03
A15: Net Cash Inflow / Outflow | B15: 371.52 | C15: 229 | D15: -333.16 | E15: 55.29 | F15: 228.99 | G15: -630.21 | H15: 171.4 | I15: 457.51 | J15: -539.2 | K15: 253.9 | L15: 88.79 | M15: -64 | N15: -622.47 | O15: 946.88 | P15: 128.54 | Q15: -35.46 | R15: 80.8
A16: Opening Cash & Cash Equivalents | B16: 448.61 | C16: 219.42 | D16: 563.97 | E16: 505.13 | F16: 277.33 | G16: 905.38 | H16: 760.94 | I16: 279.82 | J16: 817.55 | K16: 575.07 | L16: 486.28 | M16: 550.28 | N16: 1172.75 | O16: 225.87 | P16: 100.2 | Q16: 136.87 | R16: 56.07
A17: Cash & Cash Equivalent on Amalgamation / Take over / Merger
A18: Cash & Cash Equivalent of Subsidiaries under liquidations
A19: Translation adj. on reserves / op cash balances frgn subsidiaries
A20: Effect of Foreign Exchange Fluctuations | B20: -6.71 | C20: 0.19 | D20: -11.39 | E20: 3.55 | F20: -1.19 | G20: 2.16 | H20: -26.96 | I20: 23.61 | J20: 1.47 | K20: -11.42
A21: Closing Cash & Cash Equivalent | B21: 813.42 | C21: 448.61 | D21: 219.42 | E21: 563.97 | F21: 505.13 | G21: 277.33 | H21: 905.38 | I21: 760.94 | J21: 279.82 | K21: 817.55 | L21: 575.07 | M21: 486.28 | N21: 550.28 | O21: 1172.75 | P21: 228.74 | Q21: 101.41 | R21: 136.87
